{"status":"FAIL","msg":"FAIL:\n Uncaught: { message: \"Expected a RangeError to be thrown but no exception was thrown at all 1 + 1 \u003e 1 (length)\" }\n    at ../../test262/harness/assert.js:101\n    at anonymous (../../test262/test/built-ins/DataView/prototype/getInt8/index-is-out-of-range.js:48)\n\n","path":"../../test262/test/built-ins/DataView/prototype/getInt8/index-is-out-of-range.js"}