{"status":"FAIL","msg":"FAIL:\n Uncaught: { message: \"Expected a RangeError to be thrown but no exception was thrown at all\", name: \"Test262Error\" }\n    at ../../test262/harness/assert.js:101\n    at ../../test262/test/built-ins/Array/prototype/every/15.4.4.16-7-c-i-31.js:30\n\n","path":"../../test262/test/built-ins/Array/prototype/every/15.4.4.16-7-c-i-31.js","memory_kb":0,"duration":86142581}